:js


fun foo() =
  1 + 2

foo
//│ = [function foo]

foo()
//│ = 3

fun foo(x) =
  x + 1

foo(123)
//│ = 124

fun foo(x) =
  x + 1 + 2

foo(123)
//│ = 126

fun foo() = bar()
fun bar() = 42

bar()
//│ = 42

foo()
//│ = 42

fun foo() = bar()
let r = foo()
fun bar() = 42
r
//│ = 42
//│ r = 42

// * This fails to properly initialize, as expected
:re
fun foo() = bar()
let r = foo()
fun bar() = r
//│ ═══[RUNTIME ERROR] Error: MLscript call unexpectedly returned `undefined`, the forbidden value.
//│ r = undefined

// * Similar
:re
object Outer with
  fun foo() = bar()
  val r = foo()
  fun bar() = r
Outer.r
//│ ═══[RUNTIME ERROR] Error: MLscript call unexpectedly returned `undefined`, the forbidden value.


fun outerfun(x) =
  let r = x + 1
  fun nested(y) =
    r + x + y
  print(nested(x))
  nested

let f = outerfun(100)
f(200)
//│ > 301
//│ = 401
//│ f = [function nested]

// f(200)

outerfun(100)
//│ > 301
//│ = [function nested]

outerfun(100)(200)
//│ > 301
//│ = 401


// * Notice this strange JS phenomenon:
// * functions leak from the `try` scope, although things like classes do not...

:showRepl
fun test1(x) = test2(x)
fun test2(y) = y + 1
//│ REPL> Sending: block$res18 = undefined
//│ REPL> Collected:
//│ >  undefined
//│ REPL> Sending: let test2, test1;try { test1 = function test1(...args) {   runtime.checkArgs("test1", 1, true, args.length);   let x = args[0];   return runtime.checkCall(test2(x)) }; test2 = function test2(...args) {   runtime.checkArgs("test2", 1, true, args.length);   let y = args[0];   return y + 1 }; block$res18 = undefined; } catch (e) { console.log('\u200B' + e.stack + '\u200B'); }
//│ REPL> Collected:
//│ >  undefined
//│ REPL> Parsed:
//│ >  undefined
//│ REPL> Sending: try { runtime.checkCall(this.Predef.printRaw(block$res18)) } catch (e) { console.log('\u200B' + e.stack + '\u200B'); }
//│ REPL> Collected:
//│ >  undefined
//│ >  Unit { class: [class Unit] }
//│ REPL> Parsed:
//│ >  undefined
//│ >  Unit { class: [class Unit] }

test1(1)
//│ = 2


